<?xml version='1.0'?>
<sdf version='1.5'>
  <model name='fake_uav2'>
    <static>1</static>
    <!-- Solo body -->
    <link name='base_link'>
      <pose>0 0 0 0 0 0</pose>
      <visual name='base_link_inertia_visual'>
        <pose>0 0 0 0 0 0</pose>
        <geometry>
          <mesh>
            <scale>1 1 1</scale>
            <uri>model://solo/meshes/solo.stl</uri>
          </mesh>
        </geometry>
        <material>
          <script>
            <name>Gazebo/DarkGrey</name>
            <uri>file://media/materials/scripts/gazebo.material</uri>
          </script>
        </material>
      </visual>
      <gravity>1</gravity>
      <velocity_decay/>
      <self_collide>0</self_collide>
    </link>
    <link name='rotor_0'>
      <pose>0.14745 -0.14525 0.051 0 0 0</pose>
      <visual name='rotor_0_visual'>
        <pose>-0.14745 -0.14525 -0.051 0 0 0</pose>
        <geometry>
          <mesh>
            <scale>1 1 1</scale>
            <uri>model://solo/meshes/solo_prop_ccw.stl</uri>
          </mesh>
        </geometry>
        <material>
          <script>
            <name>Gazebo/Blue</name>
            <uri>file://media/materials/scripts/gazebo.material</uri>
          </script>
        </material>
      </visual>
      <gravity>1</gravity>
      <velocity_decay/>
      <self_collide>0</self_collide>
    </link>
    <joint name='rotor_0_joint' type='revolute'>
      <child>rotor_0</child>
      <parent>base_link</parent>
      <axis>
        <xyz>0 0 1</xyz>
        <limit>
          <lower>-1e+16</lower>
          <upper>1e+16</upper>
        </limit>
        <dynamics>
          <spring_reference>0</spring_reference>
          <spring_stiffness>0</spring_stiffness>
        </dynamics>
        <use_parent_model_frame>1</use_parent_model_frame>
      </axis>
    </joint>
    <link name='rotor_1'>
      <pose>-0.14745 0.14525 0.051 0 0 0</pose>
      <visual name='rotor_1_visual'>
        <pose>-0.14745 -0.14525 -0.051 0 0 0</pose>
        <geometry>
          <mesh>
            <scale>1 1 1</scale>
            <uri>model://solo/meshes/solo_prop_ccw.stl</uri>
          </mesh>
        </geometry>
        <material>
          <script>
            <name>Gazebo/Yellow</name>
            <uri>file://media/materials/scripts/gazebo.material</uri>
          </script>
        </material>
      </visual>
      <gravity>1</gravity>
      <velocity_decay/>
      <self_collide>0</self_collide>
    </link>
    <joint name='rotor_1_joint' type='revolute'>
      <child>rotor_1</child>
      <parent>base_link</parent>
      <axis>
        <xyz>0 0 1</xyz>
        <limit>
          <lower>-1e+16</lower>
          <upper>1e+16</upper>
        </limit>
        <dynamics>
          <spring_reference>0</spring_reference>
          <spring_stiffness>0</spring_stiffness>
        </dynamics>
        <use_parent_model_frame>1</use_parent_model_frame>
      </axis>
    </joint>
    <link name='rotor_2'>
      <pose>0.14745 0.14525 0.051 0 0 0</pose>
      <visual name='rotor_2_visual'>
        <pose>-0.14745 0.14525 -0.051 0 0 0</pose>
        <geometry>
          <mesh>
            <scale>1 1 1</scale>
            <uri>model://solo/meshes/solo_prop_cw.stl</uri>
          </mesh>
        </geometry>
        <material>
          <script>
            <name>Gazebo/Blue</name>
            <uri>file://media/materials/scripts/gazebo.material</uri>
          </script>
        </material>
      </visual>
      <gravity>1</gravity>
      <velocity_decay/>
      <self_collide>0</self_collide>
    </link>
    <joint name='rotor_2_joint' type='revolute'>
      <child>rotor_2</child>
      <parent>base_link</parent>
      <axis>
        <xyz>0 0 1</xyz>
        <limit>
          <lower>-1e+16</lower>
          <upper>1e+16</upper>
        </limit>
        <dynamics>
          <spring_reference>0</spring_reference>
          <spring_stiffness>0</spring_stiffness>
        </dynamics>
        <use_parent_model_frame>1</use_parent_model_frame>
      </axis>
    </joint>
    <link name='rotor_3'>
      <pose>-0.14745 -0.14525 0.051 0 0 0</pose>
      <visual name='rotor_3_visual'>
        <pose>-0.14745 0.14525 -0.051 0 0 0</pose>
        <geometry>
          <mesh>
            <scale>1 1 1</scale>
            <uri>model://solo/meshes/solo_prop_cw.stl</uri>
          </mesh>
        </geometry>
        <material>
          <script>
            <name>Gazebo/Yellow</name>
            <uri>file://media/materials/scripts/gazebo.material</uri>
          </script>
        </material>
      </visual>
      <gravity>1</gravity>
      <velocity_decay/>
      <self_collide>0</self_collide>
    </link>
    <joint name='rotor_3_joint' type='revolute'>
      <child>rotor_3</child>
      <parent>base_link</parent>
      <axis>
        <xyz>0 0 1</xyz>
        <limit>
          <lower>-1e+16</lower>
          <upper>1e+16</upper>
        </limit>
        <dynamics>
          <spring_reference>0</spring_reference>
          <spring_stiffness>0</spring_stiffness>
        </dynamics>
        <use_parent_model_frame>1</use_parent_model_frame>
      </axis>
    </joint>

    <!-- plugins: libgazebo_ros_p3d -->
    <!-- 发布真值,模拟vicon系统 -->
    <plugin name="p3d_base_controller" filename="libgazebo_ros_p3d.so">
      <alwaysOn>true</alwaysOn>
      <updateRate>50.0</updateRate>
      <bodyName>base_link</bodyName>
      <topicName>/uav2/odom</topicName>
      <gaussianNoise>0.00</gaussianNoise>
      <frameName>world</frameName>
      <xyzOffsets>0 0 0</xyzOffsets>
      <rpyOffsets>0 0 0</rpyOffsets>
    </plugin>

    <!-- 传感器开始 -->
    <!-- 前视相机 -->
    <link name='Monocular_front_link'>
      <pose>0.1 0 -0.05 0 0 0</pose>
      <inertial>
        <mass>0.001</mass>
        <inertia>
          <ixx>4.15e-6</ixx>
          <ixy>0</ixy>
          <ixz>0</ixz>
          <iyy>2.407e-6</iyy>
          <iyz>0</iyz>
          <izz>2.407e-6</izz>
        </inertia>
      </inertial>
      <visual name='visual'>
        <geometry>
          <box>
            <size>0.01 0.01 0.01</size>
          </box>
        </geometry>
      </visual>
      <sensor name='camera' type='camera'>
        <camera name='__default__'>
          <!-- FOV,120度 -->
          <horizontal_fov>2.0944</horizontal_fov>
          <image>
            <width>640</width>
            <height>480</height>
          </image>
          <clip>
            <near>0.1</near>
            <far>100</far>
          </clip>
          <noise>
            <type>gaussian</type>
            <mean>0.0</mean>
            <stddev>0.001</stddev>
          </noise>
          <lens>
            <type>custom</type>
            <custom_function>
              <c1>1.05</c1>
              <c2>4</c2>
              <f>1</f>
              <fun>tan</fun>
            </custom_function>
            <scale_to_hfov>1</scale_to_hfov>
            <cutoff_angle>3.1415</cutoff_angle>
          </lens>
        </camera>
        <always_on>1</always_on>
        <update_rate>30</update_rate>
        <visualize>0</visualize>
        <plugin name='camera_plugin' filename='libgazebo_ros_camera.so'>
            <robotNamespace>/uav2/sensor</robotNamespace>
            <alwaysOn>true</alwaysOn>
            <imageTopicName>image_raw</imageTopicName>
            <cameraInfoTopicName>camera_info</cameraInfoTopicName>
            <updateRate>30.0</updateRate>
            <cameraName>monocular_front</cameraName>
            <frameName>/monocular_front_link</frameName>
            <CxPrime>320</CxPrime>
            <Cx>320</Cx>
            <Cy>240</Cy>
            <hackBaseline>0</hackBaseline>
            <focalLength>180</focalLength>
            <distortionK1>0.0</distortionK1>
            <distortionK2>0.0</distortionK2>
            <distortionK3>0.0</distortionK3>
            <distortionT1>0.0</distortionT1>
            <distortionT2>0.0</distortionT2>
        </plugin>
      </sensor>
      <self_collide>0</self_collide>
      <kinematic>0</kinematic>
    </link>
    <!-- 前视相机关节 -->
    <joint name="Monocular_front_joint" type="fixed">
      <child>Monocular_front_link</child>
      <parent>base_link</parent>
      <axis>
        <xyz>0 0 1</xyz>
        <limit>
          <upper>0</upper>
          <lower>0</lower>
        </limit>
        <use_parent_model_frame>1</use_parent_model_frame>
      </axis>
    </joint>
    <!-- 下视相机 -->
    <link name='Monocular_down_link'>
      <pose>0 0 -0.1 0 1.5707963 0</pose>
      <inertial>
        <mass>0.001</mass>
        <inertia>
          <ixx>4.15e-6</ixx>
          <ixy>0</ixy>
          <ixz>0</ixz>
          <iyy>2.407e-6</iyy>
          <iyz>0</iyz>
          <izz>2.407e-6</izz>
        </inertia>
      </inertial>
      <visual name='visual'>
        <geometry>
          <box>
            <size>0.01 0.01 0.01</size>
          </box>
        </geometry>
      </visual>
      <sensor name='camera' type='camera'>
        <camera name='__default__'>
          <!-- FOV,120度 -->
          <horizontal_fov>2.0944</horizontal_fov>
          <image>
            <width>640</width>
            <height>480</height>
          </image>
          <clip>
            <near>0.1</near>
            <far>100</far>
          </clip>
          <noise>
            <type>gaussian</type>
            <mean>0.0</mean>
            <stddev>0.001</stddev>
          </noise>
          <lens>
            <type>custom</type>
            <custom_function>
              <c1>1.05</c1>
              <c2>4</c2>
              <f>1</f>
              <fun>tan</fun>
            </custom_function>
            <scale_to_hfov>1</scale_to_hfov>
            <cutoff_angle>3.1415</cutoff_angle>
          </lens>
        </camera>
        <always_on>1</always_on>
        <update_rate>30</update_rate>
        <visualize>0</visualize>
        <plugin name='camera_plugin' filename='libgazebo_ros_camera.so'>
            <robotNamespace>/uav2/sensor</robotNamespace>
            <alwaysOn>true</alwaysOn>
            <imageTopicName>image_raw</imageTopicName>
            <cameraInfoTopicName>camera_info</cameraInfoTopicName>
            <updateRate>30.0</updateRate>
            <cameraName>monocular_down</cameraName>
            <frameName>/monocular_down_link</frameName>
            <CxPrime>320</CxPrime>
            <Cx>320</Cx>
            <Cy>240</Cy>
            <hackBaseline>0</hackBaseline>
            <focalLength>180</focalLength>
            <distortionK1>0.0</distortionK1>
            <distortionK2>0.0</distortionK2>
            <distortionK3>0.0</distortionK3>
            <distortionT1>0.0</distortionT1>
            <distortionT2>0.0</distortionT2>
        </plugin>
      </sensor>
      <self_collide>0</self_collide>
      <kinematic>0</kinematic>
    </link>
    <!-- 下视相机关节 -->
    <joint name="Monocular_down_joint" type="fixed">
      <child>Monocular_down_link</child>
      <parent>base_link</parent>
      <axis>
        <xyz>0 0 1</xyz>
        <limit>
          <upper>0</upper>
          <lower>0</lower>
        </limit>
      </axis>
    </joint>  

    <link name="lidar_link">
      <pose>0 0 0.2 0 0.0 0</pose>
      <!-- 物理参数设置 -->
      <inertial>
        <pose>0 0 0 0 0 0</pose>
        <mass>0.1</mass>
        <inertia>
          <ixx>4.15e-6</ixx>
          <ixy>0</ixy>
          <ixz>0</ixz>
          <iyy>2.407e-6</iyy>
          <iyz>0</iyz>
          <izz>2.407e-6</izz>
        </inertia>
      </inertial>
      <!-- 显示参数设置 -->
      <visual name="visual">
        <geometry>
          <box>
            <size>0.05 0.05 0.04</size>
          </box>
        </geometry>
      </visual>
      <!-- 传感器参数设置 -->
      <sensor name="2Dlaser" type="ray">
        <ray>
          <scan>
            <horizontal>
              <samples>360</samples>
              <resolution>1</resolution>
              <!-- UST-20LX 视场为270度 -->
              <min_angle>-3.14</min_angle>
              <max_angle>3.14</max_angle>
            </horizontal>
          </scan>
          <range>
            <min>0.06</min>
            <max>5</max>
            <resolution>0.01</resolution>
          </range>
          <noise>
            <type>gaussian</type>
            <mean>0.0</mean>
            <stddev>0.000</stddev>
          </noise>
        </ray>
        <plugin name="laser" filename="libRayPlugin.so" />
        <plugin name="2Dlidar" filename="libgazebo_ros_laser.so">
          <topicName>/uav2/scan</topicName>
          <frameName>/uav2/lidar_link</frameName>
        </plugin>
        <always_on>1</always_on>
        <!-- 更新频率 10HZ -->
        <update_rate>20</update_rate>
        <visualize>false</visualize>
      </sensor>
    </link>

    <joint name="2Dlidar_joint" type="fixed">
      <child>lidar_link</child>
      <parent>base_link</parent>
      <axis>
        <xyz>0 0 1</xyz>
        <limit>
          <upper>0</upper>
          <lower>0</lower>
        </limit>
      </axis>
    </joint> 
    <!-- 传感器结束 -->
  </model>
</sdf>
